<?xml version="1.0" encoding="utf-8"?>
<!-- This URDF was automatically created by SolidWorks to URDF Exporter! Originally created by Stephen Brawner (brawner@gmail.com) 
     Commit Version: 1.6.0-1-g15f4949  Build Version: 1.6.7594.29634
     For more information, please see http://wiki.ros.org/sw_urdf_exporter -->
<robot name="fum6r_new_corsys">

  <link name= "world" />

  <joint name= "worldJ0" type="fixed">
      <origin xyz="0 0 1" rpy="0 0 0" />
      <parent
      link="world" />
    <child
      link="6RL0" />
    <dynamics damping="0.1" friction="0.1"/>
  </joint>

  <link name="6RL0">
    <inertial>
      <origin xyz="0.0028 0.0 0.0588" rpy="0 0 0" />
      <mass value="31.781" />
      <inertia
        ixx="0.37456"
        ixy="0.0"
        ixz="-0.0014"
        iyy="0.3642"
        iyz="0.0"
        izz="0.6497" />
    </inertial>
    <visual>
      <origin xyz="0 0 0" rpy="0 0 0" />
      <geometry>
        <mesh
          filename="/home/aliha1313/FUM6R-WS/src/Ros2ControlBringingUp/meshes/6RL0.STL" />
      </geometry>
      <material
        name="">
        <color rgba="0.89804 0.91765 0.92941 1" />
      </material>
    </visual>
    <collision>
      <origin xyz="0 0 0" rpy="0 0 0" />
      <geometry>
        <mesh
          filename="/home/aliha1313/FUM6R-WS/src/Ros2ControlBringingUp/meshes/6RL0.STL" />
      </geometry>
    </collision>
  </link>
  <link name="6RL1">
    <inertial>
      <origin xyz="-0.0164 -0.0196 -0.1313" rpy="0 0 0" />
      <mass value="29.9228" />
      <inertia
        ixx="0.5574"
        ixy="-0.0087"
        ixz="-0.0176"
        iyy="0.6014"
        iyz="-0.0759"
        izz="0.3616" />
    </inertial>
    <visual>
      <origin xyz="0 0 0" rpy="0 0 0" />
      <geometry>
        <mesh
          filename="/home/aliha1313/FUM6R-WS/src/Ros2ControlBringingUp/meshes/6RL1.STL" />
      </geometry>
      <material
        name="">
        <color
          rgba="0.89804 0.91765 0.92941 1" />
      </material>
    </visual>
    <collision>
      <origin
        xyz="0 0 0"
        rpy="0 0 0" />
      <geometry>
        <mesh
          filename="/home/aliha1313/FUM6R-WS/src/Ros2ControlBringingUp/meshes/6RL1.STL" />
      </geometry>
    </collision>
  </link>
  <joint name="6RJ1" type="revolute">
    <origin xyz="0 0 0.3895" rpy="0.00000000 0.00000000 0.00000000" />
    <parent link="6RL0" />
    <child link="6RL1" />
    <axis xyz="0 0 1" />
    <limit
      lower="-1.79769e+308"
      upper="1.79769e+308"
      effort="-1"
      velocity="-1" />
  </joint>
  <link name="6RL2">
    <inertial>
      <origin xyz="0.0 0.0823 0.1827" rpy="0 0 0" />
      <mass value="16.8897" />
      <inertia
        ixx="1.0003"
        ixy="0.0"
        ixz="0.0"
        iyy="1.0339"
        iyz="0.0443"
        izz="0.0665" />
    </inertial>
    <visual>
      <origin
        xyz="0 0 0"
        rpy="0 0 0" />
      <geometry>
        <mesh
          filename="/home/aliha1313/FUM6R-WS/src/Ros2ControlBringingUp/meshes/6RL2.STL" />
      </geometry>
      <material
        name="">
        <color
          rgba="0.89804 0.91765 0.92941 1" />
      </material>
    </visual>
    <collision>
      <origin
        xyz="0 0 0"
        rpy="0 0 0" />
      <geometry>
        <mesh
          filename="/home/aliha1313/FUM6R-WS/src/Ros2ControlBringingUp/meshes/6RL2.STL" />
      </geometry>
    </collision>
  </link>
  <joint name="6RJ2" type="revolute">
    <origin xyz="0 0 0" rpy="0.00000000 0.00000000 0.00000000" />
    <parent link="6RL1" />
    <child link="6RL2" />
    <axis xyz="0 1 0" />
    <limit
      lower="-1.79769e+308"
      upper="1.79769e+308"
      effort="-1"
      velocity="-1" />

    <dynamics damping="0.1" friction="0.1"/>
  </joint>
  <link name="6RL3">
    <inertial>
      <origin xyz="0.0017 -0.0031 0.1282" rpy="0 0 0" />
      <mass value="24.1602" />
      <inertia
        ixx="0.3313"
        ixy="-0.0053"
        ixz="-0.0071"
        iyy="0.7914"
        iyz="0.0190"
        izz="0.6146" />
    </inertial>
    <visual>
      <origin
        xyz="0 0 0"
        rpy="0 0 0" />
      <geometry>
        <mesh
          filename="/home/aliha1313/FUM6R-WS/src/Ros2ControlBringingUp/meshes/6RL3.STL" />
      </geometry>
      <material
        name="">
        <color
          rgba="0.898039215686275 0.917647058823529 0.929411764705882 1" />
      </material>
    </visual>
    <collision>
      <origin
        xyz="0 0 0"
        rpy="0 0 0" />
      <geometry>
        <mesh
          filename="/home/aliha1313/FUM6R-WS/src/Ros2ControlBringingUp/meshes/6RL3.STL" />
      </geometry>
    </collision>
  </link>
  <joint name="6RJ3" type="revolute">
    <origin xyz="0 0 0.6" rpy="0.00000000 0.00000000 0.00000000" />
    <parent link="6RL2" />
    <child link="6RL3" />
    <axis xyz="0 1 0" />
    <limit
      lower="-1.79769e+308"
      upper="1.79769e+308"
      effort="-1"
      velocity="-1" />
    <dynamics damping="0.1" friction="0.1"/>
  </joint>
  <link name="6RL4">
    <inertial>
      <origin xyz="-0.1232 -0.0146 0.0004" rpy="0 0 0" />
      <mass value="4.7423" />
      <inertia
        ixx="0.0183"
        ixy="-0.0037"
        ixz="0.0"
        iyy="0.0147692483277016"
        iyz="0.0325"
        izz="0.0399" />
    </inertial>
    <visual>
      <origin xyz="0 0 0" rpy="0 0 0" />
      <geometry>
        <mesh
          filename="/home/aliha1313/FUM6R-WS/src/Ros2ControlBringingUp/meshes/6RL4.STL" />
      </geometry>
      <material
        name="">
        <color
          rgba="0.898039215686275 0.917647058823529 0.929411764705882 1" />
      </material>
    </visual>
    <collision>
      <origin
        xyz="0 0 0"
        rpy="0 0 0" />
      <geometry>
        <mesh
          filename="/home/aliha1313/FUM6R-WS/src/Ros2ControlBringingUp/meshes/6RL4.STL" />
      </geometry>
    </collision>
  </link>
  <joint name="6RJ4" type="revolute">
    <origin xyz="0.6855 0 0.2" rpy="0.00000000 0.00000000 0.00000000" />
    <parent link="6RL3" />
    <child link="6RL4" />
    <axis xyz="1 0 0" />
    <limit
      lower="-1.79769e+308"
      upper="1.79769e+308"
      effort="-1"
      velocity="-1" />
    <dynamics damping="0.1" friction="0.1"/>
  </joint>
  <link name="6RL5">
    <inertial>
      <origin xyz="0.0205 -0.0131 -0.0026" rpy="0 0 0" />
      <mass value="2.615" />
      <inertia
        ixx="0.0057"
        ixy="0.0002"
        ixz="0.0001"
        iyy="0.0082"
        iyz="0.0001"
        izz="0.0065" />
    </inertial>
    <visual>
      <origin xyz="0 0 0" rpy="0 0 0" />
      <geometry>
        <mesh
          filename="/home/aliha1313/FUM6R-WS/src/Ros2ControlBringingUp/meshes/6RL5.STL" />
      </geometry>
      <material
        name="">
        <color
          rgba="0.898039215686275 0.917647058823529 0.929411764705882 1" />
      </material>
    </visual>
    <collision>
      <origin
        xyz="0 0 0"
        rpy="0 0 0" />
      <geometry>
        <mesh
          filename="/home/aliha1313/FUM6R-WS/src/Ros2ControlBringingUp/meshes/6RL5.STL" />
      </geometry>
    </collision>
  </link>
  <joint name="6RJ5" type="revolute">
    <origin xyz="0 0 0" rpy="0.00000000 0.00000000 0.00000000" />
    <parent link="6RL4" />
    <child link="6RL5" />
    <axis xyz="0 1 0" />
    <limit
      lower="-1.79769e+308"
      upper="1.79769e+308"
      effort="-1"
      velocity="-1" />
    <dynamics damping="0.1" friction="0.1"/>
  </joint>
  <link name="6RL6">
    <inertial>
      <origin xyz="0.1084 0.0 0.0" rpy="0 0 0" />
      <mass value="0.955" />
      <inertia
        ixx="0.0011"
        ixy="0.0"
        ixz="0.0"
        iyy="0.0008"
        iyz="0.0"
        izz="0.0008" />
    </inertial>
    <visual>
      <originv xyz="0 0 0" rpy="0 0 0" />
      <geometry>
        <mesh
          filename="/home/aliha1313/FUM6R-WS/src/Ros2ControlBringingUp/meshes/6RL6.STL" />
      </geometry>
      <material
        name="">
        <color
          rgba="0.898039215686275 0.917647058823529 0.929411764705882 1" />
      </material>
    </visual>
    <collision>
      <origin
        xyz="0 0 0"
        rpy="0 0 0" />
      <geometry>
        <mesh
          filename="/home/aliha1313/FUM6R-WS/src/Ros2ControlBringingUp/meshes/6RL6.STL" />
      </geometry>
    </collision>
  </link>
  <joint name="6RJ6" type="revolute">
    <origin xyz="0 0 0" rpy="0.00000000 0.00000000 0.00000000" />
    <parent link="6RL5" />
    <child link="6RL6" />
    <axis xyz="1 0 0" />
    <limit
      lower="-1.79769e+308"
      upper="1.79769e+308"
      effort="-1"
      velocity="-1" />
    <dynamics damping="0.1" friction="0.1"/>
  </joint>

  <link name="plate">
    <visual>
      <geometry>
        <box size="0.3 0.3 0.005"/>
      </geometry>
    </visual>
    <collision>
      <origin
        xyz="0 0 0"
        rpy="0 0 0" />
      <geometry>
        <box size="0.3 0.3 0.005"/>
      </geometry>
    </collision>
  </link>

  <joint name= "EEJ" type="fixed">
    <origin xyz="0.341 0 0" rpy="0 0 0" />
    <parent
      link="6RL6" />
    <child
      link="plate" />
  </joint>



  <gazebo reference="6RL0">
    <material>Gazebo/FlatBlack</material>
  </gazebo>


  <gazebo reference="6RL1">
    <material>Gazebo/FlatBlack</material>
  </gazebo>

  <gazebo reference="6RL2">
    <material>Gazebo/Yellow</material>
  </gazebo>

  <gazebo reference="6RL3">
    <material>Gazebo/Yellow</material>
  </gazebo>

  <gazebo reference="6RL4">
    <material>Gazebo/FlatBlack</material>
  </gazebo>

  <gazebo reference="6RL5">
    <material>Gazebo/FlatBlack</material>
  </gazebo>

  <gazebo reference="6RL6">
    <material>Gazebo/FlatBlack</material>
  </gazebo>

  <gazebo reference="plate">
    <material>Gazebo/Grey</material>
  </gazebo>

  <gazebo>
    <plugin name='p3d_plugin' filename='libgazebo_ros_p3d.so'>
        <body_name>6RL6</body_name>
        <frame_name>6RL0</frame_name>
        <topicName>odom</topicName>
        <update_rate>100.0</update_rate>
    </plugin>
  </gazebo>

  <gazebo>
    <plugin name='gazebo_ROS_6R_torque' 
      filename='/home/aliha1313/FUM6R-First-Steps-main/GazeboRos6RPlugin/SO_Files/libgazebo_ros_6r.so'>
    </plugin>
  </gazebo>

    <gazebo>
  <plugin filename="libgazebo_ros2_control.so" name="gazebo_ros2_control">
    <robot_sim_type>gazebo_ros2_control/GazeboSystem</robot_sim_type>
    <parameters>/home/aliha1313/FUM6R-WS/src/Ros2ControlBringingUp/config/jtc.yaml</parameters>
  </plugin>
  </gazebo>

<ros2_control name="GazeboSystem" type="system">
    <hardware>
      <plugin>gazebo_ros2_control/GazeboSystem</plugin>
    </hardware>

</robot>